In the provided snippet, error handling is performed in two distinct places:

1. **Using `catchError` within the `pipe()`**: Handles errors within the observable pipeline.
2. **Using the `error` callback in `subscribe()`**: Handles errors that reach the subscriber after passing through the observable pipeline.

Here’s how the errors are processed and caught in these two places:

---

### **1. Error Handling in `catchError`**

#### **What It Does:**
- The `catchError` operator intercepts any error that occurs in the observable pipeline.
- It allows you to process the error, log it, transform it, or return a fallback observable.
- In the provided code, `catchError` calls the `handleError` method.

#### **Types of Errors Caught by `catchError`:**
- **Network Errors**: If the HTTP request fails due to issues like server unavailability, DNS problems, or a timeout.
- **HTTP Errors**: If the server returns an error status code (e.g., `404 Not Found`, `500 Internal Server Error`).
- **Observable Errors**: If an error is thrown within the observable stream itself.

#### **What Happens in This Code:**
```typescript
.pipe(
  catchError(this.handleError)
)
```
- **Steps**:
  1. If an error occurs in the `http.get` request or during observable processing, `catchError` intercepts it.
  2. The `handleError` method is invoked to process the error.

#### **`handleError` Logic**:
```typescript
private handleError(error: any): Observable<never> {
  console.error('An error occurred:', error); // Logs the error to the console
  return throwError(() => new Error('Failed to fetch profiles.')); // Returns a new error observable
}
```
- **Logs**: The error details are logged to the console for debugging.
- **Returns**: A new observable that emits an error using `throwError`. This new observable terminates the stream.

#### **Why This is Useful**:
- Centralized Error Handling: You can define how errors are processed for the entire observable chain in one place.
- Fallback Values: Instead of terminating with an error, you could return a fallback value (e.g., `of([])` for an empty array).

---

### **2. Error Handling in the `error` Callback of `subscribe()`**

#### **What It Does:**
- The `error` callback in `subscribe()` handles errors that propagate past the observable pipeline (including any transformed errors from `catchError`).

#### **Types of Errors Caught by `subscribe()`’s `error` Callback:**
- **Errors Not Fully Handled by `catchError`**:
  - If `catchError` rethrows the error (as in this case using `throwError`), it is caught here.
- **Transformed Errors**:
  - The error produced by `catchError` (e.g., `'Failed to fetch profiles.'`) will propagate here if not resolved earlier.

#### **What Happens in This Code:**
```typescript
.subscribe({
  next: (profiles) => {
    console.log('Received profiles:', profiles); // Success handling
  },
  error: (error) => {
    console.error('Error fetching profiles:', error); // Additional error handling
  }
});
```
- **If `catchError` rethrows an error**:
  - The `error` callback in `subscribe()` is invoked.
  - It logs the error to the console as `'Error fetching profiles: Failed to fetch profiles.'`.

#### **Why This is Useful**:
- Final Fallback: This is the last opportunity to handle any errors not resolved within the observable pipeline.
- Graceful Degradation: You can use this to notify users or show a fallback UI.

---

### **How the Two Levels of Error Handling Interact**

1. **Error Propagation**:
   - If an error occurs during the `http.get()` request, it is propagated into the observable chain.
   - `catchError` intercepts this error, processes it using `handleError`, and replaces it with a new error observable (`throwError`).

2. **Error Reaches `subscribe`**:
   - The new error observable from `catchError` propagates to the `error` callback in `subscribe()`.

---

### **Execution Flow Example**

#### **Scenario 1: Server Returns `500 Internal Server Error`**
1. `http.get()` request encounters a `500 Internal Server Error`.
2. `catchError` intercepts the error and logs it via `handleError`.
3. `catchError` rethrows the error as `'Failed to fetch profiles.'` using `throwError`.
4. The `error` callback in `subscribe()` logs the final error.

#### **Scenario 2: Server is Unreachable**
1. `http.get()` request fails due to a network issue.
2. `catchError` intercepts the error and logs it via `handleError`.
3. `catchError` rethrows the error as `'Failed to fetch profiles.'`.
4. The `error` callback in `subscribe()` logs the final error.

---

### **Why Use Both Levels of Error Handling?**

- **`catchError`**:
  - Centralizes error handling in the observable pipeline.
  - Can transform or recover from errors (e.g., returning a fallback value).
  - Ensures cleaner, reusable logic.

- **`subscribe`’s `error` Callback**:
  - Acts as a final fallback for errors that `catchError` does not fully resolve.
  - Typically used for user-facing actions (e.g., showing a toast message or updating the UI).

---

### **Summary**
- **Errors in `catchError`**: Handle errors from the observable pipeline, log them, or transform them into a new observable.
- **Errors in `subscribe`**: Handle errors propagated beyond `catchError` as a fallback, often for user-facing notifications.
- **Flow**: 
  1. Error occurs in the request or observable chain.
  2. `catchError` intercepts it for processing.
  3. If rethrown, it propagates to `subscribe` for final handling.

